Workbook

Sheet How to use
A1: Kushii Gifts — Enquiry & Order Tracker
A3: Log every WhatsApp enquiry here, including the ones that do not buy. After Diwali the Review tab shows what sold, what converted and which reels brought customers.
A5: Tabs
A6: Orders — one row per product in an enquiry. Several products for one customer = several rows with the same Order ID.
A7: Quote Calculator — type product IDs and quantities to get the slab price and a ready-to-paste WhatsApp quote.
A8: Products — your catalogue (item 45 removed). Fill in your Cost per item to see margins.
A9: Discount Slabs — your volume discounts. Change them here and every price updates.
A10: Review — season summary: conversion, revenue, discounts, sources, top products.
A12: Colour key
A13: Blue text on a yellow cell = you type here. Black text = calculated automatically, do not overwrite.
A14: Red highlight in Orders = total discount above the 15% cap.
A16: Row 5 in Orders is an example. Overwrite or delete it when you start.
... A18: “Won” on the Review tab = Advance received, In production, Dispatched or Delivered.

Sheet Orders
A1: Enquiries & Orders
A2: One row per product. Yellow = type here; grey = calculated. Row 5 is an example.
A4: Order ID | B4: Enquiry date | C4: Customer name | D4: Phone | E4: Type | F4: Occasion | G4: Source | H4: Which reel / referrer | I4: City | J4: Product ID | K4: Product name | L4: Qty | M4: List price (₹) | N4: Slab discount | O4: Extra discount | P4: Final unit price (₹) | Q4: Product total (₹) | R4: Customisation + delivery (₹) | S4: Order value (₹) | T4: Need-by date | U4: Status | V4: Advance received (₹) | W4: Won? | X4: Balance due (₹) | Y4: Dispatch date | Z4: Courier & tracking | AA4: Lost reason | AB4: Notes | AC4: List value (helper)
A5: KG-001 | B5: 46316 | C5: Kavitha | D5: 98xxxxxx01 | E5: Personal | F5: Diwali | G5: Instagram reel | H5: "Don't give them a return gift" reel | I5: Hyderabad | J5: 37 | K5: =IF(J5="","",IFERROR(INDEX(Products!$B$5:$B$89,MATCH(J5,Products!$A$5:$A$89,0)),"Check ID")) -> Raw Silk Bag | L5: 200 | M5: =IF(J5="","",IFERROR(INDEX(Products!$E$5:$E$89,MATCH(J5,Products!$A$5:$A$89,0)),0)) -> 190 | N5: =IF(L5="","",IFERROR(VLOOKUP(L5,'Discount Slabs'!$A$5:$B$9,2,TRUE()),0)) -> 0.12 | O5: 0.02 | P5: =IF(OR(J5="",L5=""),"",ROUND(M5*(1-N5-N(O5)),0)) -> 163 | Q5: =IF(P5="","",P5*L5) -> 32600 | R5: 0 | S5: =IF(Q5="","",Q5+N(R5)) -> 32600 | T5: 46328 | U5: Delivered | V5: 30000 | W5: =IF(OR(U5="Advance received",U5="In production",U5="Dispatched",U5="Delivered"),"Won","") -> Won | X5: =IF(S5="","",S5-N(V5)) -> 2600 | AB5: Asked for 15%; gave 12% slab + 2% and free thank-you tags | AC5: =IF(P5="","",L5*M5) -> 38000
A6: KG-001 | B6: 46316 | C6: Kavitha | J6: 7 | K6: =IF(J6="","",IFERROR(INDEX(Products!$B$5:$B$89,MATCH(J6,Products!$A$5:$A$89,0)),"Check ID")) -> Coffee Dabra Set | L6: 400 | M6: =IF(J6="","",IFERROR(INDEX(Products!$E$5:$E$89,MATCH(J6,Products!$A$5:$A$89,0)),0)) -> 440 | N6: =IF(L6="","",IFERROR(VLOOKUP(L6,'Discount Slabs'!$A$5:$B$9,2,TRUE()),0)) -> 0.15 | O6: 0 | P6: =IF(OR(J6="",L6=""),"",ROUND(M6*(1-N6-N(O6)),0)) -> 374 | Q6: =IF(P6="","",P6*L6) -> 149600 | R6: 4000 | S6: =IF(Q6="","",Q6+N(R6)) -> 153600 | W6: =IF(OR(U6="Advance received",U6="In production",U6="Dispatched",U6="Delivered"),"Won","") | X6: =IF(S6="","",S6-N(V6)) -> 153600 | AC6: =IF(P6="","",L6*M6) -> 176000
A7: KG-002 | B7: 46316 | C7: Divya | D7: 9966666527 | E7: Personal | F7: Diwali | G7: Instagram reel | K7: =IF(J7="","",IFERROR(INDEX(Products!$B$5:$B$89,MATCH(J7,Products!$A$5:$A$89,0)),"Check ID")) | L7: 30 | M7: =IF(J7="","",IFERROR(INDEX(Products!$E$5:$E$89,MATCH(J7,Products!$A$5:$A$89,0)),0)) | N7: =IF(L7="","",IFERROR(VLOOKUP(L7,'Discount Slabs'!$A$5:$B$9,2,TRUE()),0)) -> 0.05 | P7: =IF(OR(J7="",L7=""),"",ROUND(M7*(1-N7-N(O7)),0)) | Q7: =IF(P7="","",P7*L7) | S7: =IF(Q7="","",Q7+N(R7)) | U7: New enquiry | W7: =IF(OR(U7="Advance received",U7="In production",U7="Dispatched",U7="Delivered"),"Won","") | X7: =IF(S7="","",S7-N(V7)) | AC7: =IF(P7="","",L7*M7)
A8: KG-003 | B8: 46317 | C8: Dhruvi | D8: 9167671510 | E8: Corporate | F8: Diwali | G8: Instagram reel | J8: 6 | K8: =IF(J8="","",IFERROR(INDEX(Products!$B$5:$B$89,MATCH(J8,Products!$A$5:$A$89,0)),"Check ID")) -> Spice Box 3 | L8: 50 | M8: =IF(J8="","",IFERROR(INDEX(Products!$E$5:$E$89,MATCH(J8,Products!$A$5:$A$89,0)),0)) -> 665 | N8: =IF(L8="","",IFERROR(VLOOKUP(L8,'Discount Slabs'!$A$5:$B$9,2,TRUE()),0)) -> 0.08 | O8: 0.02 | P8: =IF(OR(J8="",L8=""),"",ROUND(M8*(1-N8-N(O8)),0)) -> 599 | Q8: =IF(P8="","",P8*L8) -> 29950 | S8: =IF(Q8="","",Q8+N(R8)) -> 29950 | W8: =IF(OR(U8="Advance received",U8="In production",U8="Dispatched",U8="Delivered"),"Won","") | X8: =IF(S8="","",S8-N(V8)) -> 29950 | AC8: =IF(P8="","",L8*M8) -> 33250
A9: KG-003 | B9: 46317 | C9: Dhruvi | D9: 9167671510 | E9: Corporate | F9: Diwali | G9: Instagram reel | J9: 9 | K9: =IF(J9="","",IFERROR(INDEX(Products!$B$5:$B$89,MATCH(J9,Products!$A$5:$A$89,0)),"Check ID")) -> Shanku Chakra Diyas | L9: 50 | M9: =IF(J9="","",IFERROR(INDEX(Products!$E$5:$E$89,MATCH(J9,Products!$A$5:$A$89,0)),0)) -> 540 | N9: =IF(L9="","",IFERROR(VLOOKUP(L9,'Discount Slabs'!$A$5:$B$9,2,TRUE()),0)) -> 0.08 | P9: =IF(OR(J9="",L9=""),"",ROUND(M9*(1-N9-N(O9)),0)) -> 497 | Q9: =IF(P9="","",P9*L9) -> 24850 | S9: =IF(Q9="","",Q9+N(R9)) -> 24850 | W9: =IF(OR(U9="Advance received",U9="In production",U9="Dispatched",U9="Delivered"),"Won","") | X9: =IF(S9="","",S9-N(V9)) -> 24850 | AC9: =IF(P9="","",L9*M9) -> 27000
A10: KG-003 | B10: 46317 | C10: Dhruvi | D10: 9167671510 | E10: Corporate | F10: Diwali | G10: Instagram reel | J10: 10 | K10: =IF(J10="","",IFERROR(INDEX(Products!$B$5:$B$89,MATCH(J10,Products!$A$5:$A$89,0)),"Check ID")) -> Lotus Stand | L10: 50 | M10: =IF(J10="","",IFERROR(INDEX(Products!$E$5:$E$89,MATCH(J10,Products!$A$5:$A$89,0)),0)) -> 340 | N10: =IF(L10="","",IFERROR(VLOOKUP(L10,'Discount Slabs'!$A$5:$B$9,2,TRUE()),0)) -> 0.08 | P10: =IF(OR(J10="",L10=""),"",ROUND(M10*(1-N10-N(O10)),0)) -> 313 | Q10: =IF(P10="","",P10*L10) -> 15650 | S10: =IF(Q10="","",Q10+N(R10)) -> 15650 | W10: =IF(OR(U10="Advance received",U10="In production",U10="Dispatched",U10="Delivered"),"Won","") | X10: =IF(S10="","",S10-N(V10)) -> 15650 | AC10: =IF(P10="","",L10*M10) -> 17000
A11: KG-003 | B11: 46317 | C11: Dhruvi | D11: 9167671510 | E11: Corporate | F11: Diwali | G11: Instagram reel | J11: 11 | K11: =IF(J11="","",IFERROR(INDEX(Products!$B$5:$B$89,MATCH(J11,Products!$A$5:$A$89,0)),"Check ID")) -> Lotus Diyas | L11: 50 | M11: =IF(J11="","",IFERROR(INDEX(Products!$E$5:$E$89,MATCH(J11,Products!$A$5:$A$89,0)),0)) -> 430 | N11: =IF(L11="","",IFERROR(VLOOKUP(L11,'Discount Slabs'!$A$5:$B$9,2,TRUE()),0)) -> 0.08 | P11: =IF(OR(J11="",L11=""),"",ROUND(M11*(1-N11-N(O11)),0)) -> 396 | Q11: =IF(P11="","",P11*L11) -> 19800 | S11: =IF(Q11="","",Q11+N(R11)) -> 19800 | U11: Delivered | W11: =IF(OR(U11="Advance received",U11="In production",U11="Dispatched",U11="Delivered"),"Won","") -> Won | X11: =IF(S11="","",S11-N(V11)) -> 19800 | AC11: =IF(P11="","",L11*M11) -> 21500
A12: KG-004 | B12: 46321 | C12: Mumbaiya Tapri - Aarti S | D12: 61401601675 | E12: Corporate | F12: Other | G12: Instagram reel | J12: 2 | K12: =IF(J12="","",IFERROR(INDEX(Products!$B$5:$B$89,MATCH(J12,Products!$A$5:$A$89,0)),"Check ID")) -> Spice Box 1 | L12: 20 | M12: =IF(J12="","",IFERROR(INDEX(Products!$E$5:$E$89,MATCH(J12,Products!$A$5:$A$89,0)),0)) -> 650 | N12: =IF(L12="","",IFERROR(VLOOKUP(L12,'Discount Slabs'!$A$5:$B$9,2,TRUE()),0)) -> 0 | O12: 0.04 | P12: =IF(OR(J12="",L12=""),"",ROUND(M12*(1-N12-N(O12)),0)) -> 624 | Q12: =IF(P12="","",P12*L12) -> 12480 | S12: =IF(Q12="","",Q12+N(R12)) -> 12480 | W12: =IF(OR(U12="Advance received",U12="In production",U12="Dispatched",U12="Delivered"),"Won","") | X12: =IF(S12="","",S12-N(V12)) -> 12480 | AC12: =IF(P12="","",L12*M12) -> 13000
K13: =IF(J13="","",IFERROR(INDEX(Products!$B$5:$B$89,MATCH(J13,Products!$A$5:$A$89,0)),"Check ID")) | M13: =IF(J13="","",IFERROR(INDEX(Products!$E$5:$E$89,MATCH(J13,Products!$A$5:$A$89,0)),0)) | N13: =IF(L13="","",IFERROR(VLOOKUP(L13,'Discount Slabs'!$A$5:$B$9,2,TRUE()),0)) | P13: =IF(OR(J13="",L13=""),"",ROUND(M13*(1-N13-N(O13)),0)) | Q13: =IF(P13="","",P13*L13) | S13: =IF(Q13="","",Q13+N(R13)) | W13: =IF(OR(U13="Advance received",U13="In production",U13="Dispatched",U13="Delivered"),"Won","") | X13: =IF(S13="","",S13-N(V13)) | AC13: =IF(P13="","",L13*M13)
K14: =IF(J14="","",IFERROR(INDEX(Products!$B$5:$B$89,MATCH(J14,Products!$A$5:$A$89,0)),"Check ID")) | M14: =IF(J14="","",IFERROR(INDEX(Products!$E$5:$E$89,MATCH(J14,Products!$A$5:$A$89,0)),0)) | N14: =IF(L14="","",IFERROR(VLOOKUP(L14,'Discount Slabs'!$A$5:$B$9,2,TRUE()),0)) | P14: =IF(OR(J14="",L14=""),"",ROUND(M14*(1-N14-N(O14)),0)) | Q14: =IF(P14="","",P14*L14) | S14: =IF(Q14="","",Q14+N(R14)) | W14: =IF(OR(U14="Advance received",U14="In production",U14="Dispatched",U14="Delivered"),"Won","") | X14: =IF(S14="","",S14-N(V14)) | AC14: =IF(P14="","",L14*M14)
K15: =IF(J15="","",IFERROR(INDEX(Products!$B$5:$B$89,MATCH(J15,Products!$A$5:$A$89,0)),"Check ID")) | M15: =IF(J15="","",IFERROR(INDEX(Products!$E$5:$E$89,MATCH(J15,Products!$A$5:$A$89,0)),0)) | N15: =IF(L15="","",IFERROR(VLOOKUP(L15,'Discount Slabs'!$A$5:$B$9,2,TRUE()),0)) | P15: =IF(OR(J15="",L15=""),"",ROUND(M15*(1-N15-N(O15)),0)) | Q15: =IF(P15="","",P15*L15) | S15: =IF(Q15="","",Q15+N(R15)) | W15: =IF(OR(U15="Advance received",U15="In production",U15="Dispatched",U15="Delivered"),"Won","") | X15: =IF(S15="","",S15-N(V15)) | AC15: =IF(P15="","",L15*M15)
K16: =IF(J16="","",IFERROR(INDEX(Products!$B$5:$B$89,MATCH(J16,Products!$A$5:$A$89,0)),"Check ID")) | M16: =IF(J16="","",IFERROR(INDEX(Products!$E$5:$E$89,MATCH(J16,Products!$A$5:$A$89,0)),0)) | N16: =IF(L16="","",IFERROR(VLOOKUP(L16,'Discount Slabs'!$A$5:$B$9,2,TRUE()),0)) | P16: =IF(OR(J16="",L16=""),"",ROUND(M16*(1-N16-N(O16)),0)) | Q16: =IF(P16="","",P16*L16) | S16: =IF(Q16="","",Q16+N(R16)) | W16: =IF(OR(U16="Advance received",U16="In production",U16="Dispatched",U16="Delivered"),"Won","") | X16: =IF(S16="","",S16-N(V16)) | AC16: =IF(P16="","",L16*M16)
K17: =IF(J17="","",IFERROR(INDEX(Products!$B$5:$B$89,MATCH(J17,Products!$A$5:$A$89,0)),"Check ID")) | M17: =IF(J17="","",IFERROR(INDEX(Products!$E$5:$E$89,MATCH(J17,Products!$A$5:$A$89,0)),0)) | N17: =IF(L17="","",IFERROR(VLOOKUP(L17,'Discount Slabs'!$A$5:$B$9,2,TRUE()),0)) | P17: =IF(OR(J17="",L17=""),"",ROUND(M17*(1-N17-N(O17)),0)) | Q17: =IF(P17="","",P17*L17) | S17: =IF(Q17="","",Q17+N(R17)) | W17: =IF(OR(U17="Advance received",U17="In production",U17="Dispatched",U17="Delivered"),"Won","") | X17: =IF(S17="","",S17-N(V17)) | AC17: =IF(P17="","",L17*M17)
K18: =IF(J18="","",IFERROR(INDEX(Products!$B$5:$B$89,MATCH(J18,Products!$A$5:$A$89,0)),"Check ID")) | M18: =IF(J18="","",IFERROR(INDEX(Products!$E$5:$E$89,MATCH(J18,Products!$A$5:$A$89,0)),0)) | N18: =IF(L18="","",IFERROR(VLOOKUP(L18,'Discount Slabs'!$A$5:$B$9,2,TRUE()),0)) | P18: =IF(OR(J18="",L18=""),"",ROUND(M18*(1-N18-N(O18)),0)) | Q18: =IF(P18="","",P18*L18) | S18: =IF(Q18="","",Q18+N(R18)) | W18: =IF(OR(U18="Advance received",U18="In production",U18="Dispatched",U18="Delivered"),"Won","") | X18: =IF(S18="","",S18-N(V18)) | AC18: =IF(P18="","",L18*M18)
K19: =IF(J19="","",IFERROR(INDEX(Products!$B$5:$B$89,MATCH(J19,Products!$A$5:$A$89,0)),"Check ID")) | M19: =IF(J19="","",IFERROR(INDEX(Products!$E$5:$E$89,MATCH(J19,Products!$A$5:$A$89,0)),0)) | N19: =IF(L19="","",IFERROR(VLOOKUP(L19,'Discount Slabs'!$A$5:$B$9,2,TRUE()),0)) | P19: =IF(OR(J19="",L19=""),"",ROUND(M19*(1-N19-N(O19)),0)) | Q19: =IF(P19="","",P19*L19) | S19: =IF(Q19="","",Q19+N(R19)) | W19: =IF(OR(U19="Advance received",U19="In production",U19="Dispatched",U19="Delivered"),"Won","") | X19: =IF(S19="","",S19-N(V19)) | AC19: =IF(P19="","",L19*M19)
K20: =IF(J20="","",IFERROR(INDEX(Products!$B$5:$B$89,MATCH(J20,Products!$A$5:$A$89,0)),"Check ID")) | M20: =IF(J20="","",IFERROR(INDEX(Products!$E$5:$E$89,MATCH(J20,Products!$A$5:$A$89,0)),0)) | N20: =IF(L20="","",IFERROR(VLOOKUP(L20,'Discount Slabs'!$A$5:$B$9,2,TRUE()),0)) | P20: =IF(OR(J20="",L20=""),"",ROUND(M20*(1-N20-N(O20)),0)) | Q20: =IF(P20="","",P20*L20) | S20: =IF(Q20="","",Q20+N(R20)) | W20: =IF(OR(U20="Advance received",U20="In production",U20="Dispatched",U20="Delivered"),"Won","") | X20: =IF(S20="","",S20-N(V20)) | AC20: =IF(P20="","",L20*M20)
K21: =IF(J21="","",IFERROR(INDEX(Products!$B$5:$B$89,MATCH(J21,Products!$A$5:$A$89,0)),"Check ID")) | M21: =IF(J21="","",IFERROR(INDEX(Products!$E$5:$E$89,MATCH(J21,Products!$A$5:$A$89,0)),0)) | N21: =IF(L21="","",IFERROR(VLOOKUP(L21,'Discount Slabs'!$A$5:$B$9,2,TRUE()),0)) | P21: =IF(OR(J21="",L21=""),"",ROUND(M21*(1-N21-N(O21)),0)) | Q21: =IF(P21="","",P21*L21) | S21: =IF(Q21="","",Q21+N(R21)) | W21: =IF(OR(U21="Advance received",U21="In production",U21="Dispatched",U21="Delivered"),"Won","") | X21: =IF(S21="","",S21-N(V21)) | AC21: =IF(P21="","",L21*M21)
K22: =IF(J22="","",IFERROR(INDEX(Products!$B$5:$B$89,MATCH(J22,Products!$A$5:$A$89,0)),"Check ID")) | M22: =IF(J22="","",IFERROR(INDEX(Products!$E$5:$E$89,MATCH(J22,Products!$A$5:$A$89,0)),0)) | N22: =IF(L22="","",IFERROR(VLOOKUP(L22,'Discount Slabs'!$A$5:$B$9,2,TRUE()),0)) | P22: =IF(OR(J22="",L22=""),"",ROUND(M22*(1-N22-N(O22)),0)) | Q22: =IF(P22="","",P22*L22) | S22: =IF(Q22="","",Q22+N(R22)) | W22: =IF(OR(U22="Advance received",U22="In production",U22="Dispatched",U22="Delivered"),"Won","") | X22: =IF(S22="","",S22-N(V22)) | AC22: =IF(P22="","",L22*M22)
K23: =IF(J23="","",IFERROR(INDEX(Products!$B$5:$B$89,MATCH(J23,Products!$A$5:$A$89,0)),"Check ID")) | M23: =IF(J23="","",IFERROR(INDEX(Products!$E$5:$E$89,MATCH(J23,Products!$A$5:$A$89,0)),0)) | N23: =IF(L23="","",IFERROR(VLOOKUP(L23,'Discount Slabs'!$A$5:$B$9,2,TRUE()),0)) | P23: =IF(OR(J23="",L23=""),"",ROUND(M23*(1-N23-N(O23)),0)) | Q23: =IF(P23="","",P23*L23) | S23: =IF(Q23="","",Q23+N(R23)) | W23: =IF(OR(U23="Advance received",U23="In production",U23="Dispatched",U23="Delivered"),"Won","") | X23: =IF(S23="","",S23-N(V23)) | AC23: =IF(P23="","",L23*M23)
K24: =IF(J24="","",IFERROR(INDEX(Products!$B$5:$B$89,MATCH(J24,Products!$A$5:$A$89,0)),"Check ID")) | M24: =IF(J24="","",IFERROR(INDEX(Products!$E$5:$E$89,MATCH(J24,Products!$A$5:$A$89,0)),0)) | N24: =IF(L24="","",IFERROR(VLOOKUP(L24,'Discount Slabs'!$A$5:$B$9,2,TRUE()),0)) | P24: =IF(OR(J24="",L24=""),"",ROUND(M24*(1-N24-N(O24)),0)) | Q24: =IF(P24="","",P24*L24) | S24: =IF(Q24="","",Q24+N(R24)) | W24: =IF(OR(U24="Advance received",U24="In production",U24="Dispatched",U24="Delivered"),"Won","") | X24: =IF(S24="","",S24-N(V24)) | AC24: =IF(P24="","",L24*M24)
... K504: =IF(J504="","",IFERROR(INDEX(Products!$B$5:$B$89,MATCH(J504,Products!$A$5:$A$89,0)),"Check ID")) | M504: =IF(J504="","",IFERROR(INDEX(Products!$E$5:$E$89,MATCH(J504,Products!$A$5:$A$89,0)),0)) | N504: =IF(L504="","",IFERROR(VLOOKUP(L504,'Discount Slabs'!$A$5:$B$9,2,TRUE()),0)) | P504: =IF(OR(J504="",L504=""),"",ROUND(M504*(1-N504-N(O504)),0)) | Q504: =IF(P504="","",P504*L504) | S504: =IF(Q504="","",Q504+N(R504)) | W504: =IF(OR(U504="Advance received",U504="In production",U504="Dispatched",U504="Delivered"),"Won","") | X504: =IF(S504="","",S504-N(V504)) | AC504: =IF(P504="","",L504*M504)

Sheet Quote Calculator
A1: Quote Calculator
A2: Type the customer name, product IDs and quantities (yellow). Copy the WhatsApp text from cell A16.
A3: Customer name | B3: Aarti S | D3: Customisation + delivery (₹) | F3: 0
A5: Product ID | B5: Product | C5: Qty | D5: List price (₹) | E5: Slab discount | F5: Unit price (₹) | G5: Line total (₹)
A6: 2 | B6: =IF(A6="","",IFERROR(INDEX(Products!$B$5:$B$89,MATCH(A6,Products!$A$5:$A$89,0)),"Check ID")) -> Spice Box 1 | C6: 20 | D6: =IF(A6="","",IFERROR(INDEX(Products!$E$5:$E$89,MATCH(A6,Products!$A$5:$A$89,0)),0)) -> 650 | E6: 0.04 | F6: =IF(OR(A6="",C6=""),"",ROUND(D6*(1-E6),0)) -> 624 | G6: =IF(F6="","",F6*C6) -> 12480 | H6: =IF(F6="","",B6&": "&C6&" pcs × ₹"&TEXT(F6,"#,##0")&IF(E6>0," (after "&TEXT(E6,"0%")&" volume discount)","")&" = ₹"&TEXT(G6,"#,##0")&CHAR(10)) -> Spice Box 1: 20 pcs × ₹624 (after 4% volume discount) = ₹12,480
H7: =IF(F7="","",B7&": "&C7&" pcs × ₹"&TEXT(F7,"#,##0")&IF(E7>0," (after "&TEXT(E7,"0%")&" volume discount)","")&" = ₹"&TEXT(G7,"#,##0")&CHAR(10))
H8: =IF(F8="","",B8&": "&C8&" pcs × ₹"&TEXT(F8,"#,##0")&IF(E8>0," (after "&TEXT(E8,"0%")&" volume discount)","")&" = ₹"&TEXT(G8,"#,##0")&CHAR(10))
H9: =IF(F9="","",B9&": "&C9&" pcs × ₹"&TEXT(F9,"#,##0")&IF(E9>0," (after "&TEXT(E9,"0%")&" volume discount)","")&" = ₹"&TEXT(G9,"#,##0")&CHAR(10))
B10: =IF(A10="","",IFERROR(INDEX(Products!$B$5:$B$89,MATCH(A10,Products!$A$5:$A$89,0)),"Check ID")) | D10: =IF(A10="","",IFERROR(INDEX(Products!$E$5:$E$89,MATCH(A10,Products!$A$5:$A$89,0)),0)) | E10: =IF(C10="","",IFERROR(VLOOKUP(C10,'Discount Slabs'!$A$5:$B$9,2,TRUE()),0)) | F10: =IF(OR(A10="",C10=""),"",ROUND(D10*(1-E10),0)) | G10: =IF(F10="","",F10*C10) | H10: =IF(F10="","",B10&": "&C10&" pcs × ₹"&TEXT(F10,"#,##0")&IF(E10>0," (after "&TEXT(E10,"0%")&" volume discount)","")&" = ₹"&TEXT(G10,"#,##0")&CHAR(10))
F12: Products total | G12: =SUM(G6:G10) -> 12480
F13: Grand total | G13: =G12+N(F3) -> 12480
A15: WhatsApp quote (copy this cell):
A16: ="Thank you, "&B3&"! Here is your quote from Kushii Gifts:"&CHAR(10)&CHAR(10)&H6&H7&H8&H9&H10&CHAR(10)&IF(N(F3)>0,"Customisation + delivery: ₹"&TEXT(F3,"#,##0")&CHAR(10),"")&"Total: ₹"&TEXT(G13,"#,##0")&CHAR(10)&CHAR(10)&"This price is held for 48 hours as festive stock moves fast. A 50% advance confirms your order. Shall I reserve it for you?" -> Thank you, Aarti S! Here is your quote from Kushii Gifts: Spice Box 1: 20 pcs × ₹624 (after 4% volume discount) = ₹12,480 Total: ₹12,480 This price is held for 48 hours as festive stock moves fast. A 50% advance confirms your order. Shall I reserve it for you?

Sheet Review
A1: Season Review
A2: Everything below is calculated from the Orders tab. Rows = product lines; Orders = distinct Order IDs.
A4: Enquiries (distinct Order IDs) | B4: =SUMPRODUCT((Orders!$A$5:$A$504<>"")/COUNTIF(Orders!$A$5:$A$504,Orders!$A$5:$A$504&"")) -> 4
A5: Won orders (distinct Order IDs) | B5: =SUMPRODUCT((Orders!$W$5:$W$504="Won")/COUNTIFS(Orders!$A$5:$A$504,Orders!$A$5:$A$504&"",Orders!$W$5:$W$504,Orders!$W$5:$W$504&"")) -> 2
A6: Conversion rate | B6: =IFERROR(B5/B4,0) -> 0.5
A7: Revenue won (₹, incl. delivery) | B7: =SUMIFS(Orders!$S$5:$S$504,Orders!$W$5:$W$504,"Won") -> 52400
A8: Average order value (₹) | B8: =IFERROR(B7/B5,0) -> 26200
A9: Pieces sold | B9: =SUMIFS(Orders!$L$5:$L$504,Orders!$W$5:$W$504,"Won") -> 250
A10: Average discount on won lines | B10: =IFERROR(1-SUMIFS(Orders!$Q$5:$Q$504,Orders!$W$5:$W$504,"Won")/SUMIFS(Orders!$AC$5:$AC$504,Orders!$W$5:$W$504,"Won"),0) -> 0.11932773
A11: Balance still to collect (₹) | B11: =SUMIFS(Orders!$X$5:$X$504,Orders!$W$5:$W$504,"Won") -> 22400
A13: By source | B13: Product lines | C13: Won lines | D13: Revenue won (₹)
A14: Instagram reel | B14: =COUNTIF(Orders!$G$5:$G$504,A14) -> 7 | C14: =COUNTIFS(Orders!$G$5:$G$504,A14,Orders!$W$5:$W$504,"Won") -> 2 | D14: =SUMIFS(Orders!$S$5:$S$504,Orders!$G$5:$G$504,A14,Orders!$W$5:$W$504,"Won") -> 52400
A15: Instagram profile | B15: =COUNTIF(Orders!$G$5:$G$504,A15) -> 0 | C15: =COUNTIFS(Orders!$G$5:$G$504,A15,Orders!$W$5:$W$504,"Won") -> 0 | D15: =SUMIFS(Orders!$S$5:$S$504,Orders!$G$5:$G$504,A15,Orders!$W$5:$W$504,"Won") -> 0
A16: Instagram DM | B16: =COUNTIF(Orders!$G$5:$G$504,A16) -> 0 | C16: =COUNTIFS(Orders!$G$5:$G$504,A16,Orders!$W$5:$W$504,"Won") -> 0 | D16: =SUMIFS(Orders!$S$5:$S$504,Orders!$G$5:$G$504,A16,Orders!$W$5:$W$504,"Won") -> 0
A17: Website | B17: =COUNTIF(Orders!$G$5:$G$504,A17) -> 0 | C17: =COUNTIFS(Orders!$G$5:$G$504,A17,Orders!$W$5:$W$504,"Won") -> 0 | D17: =SUMIFS(Orders!$S$5:$S$504,Orders!$G$5:$G$504,A17,Orders!$W$5:$W$504,"Won") -> 0
A18: Referral | B18: =COUNTIF(Orders!$G$5:$G$504,A18) -> 0 | C18: =COUNTIFS(Orders!$G$5:$G$504,A18,Orders!$W$5:$W$504,"Won") -> 0 | D18: =SUMIFS(Orders!$S$5:$S$504,Orders!$G$5:$G$504,A18,Orders!$W$5:$W$504,"Won") -> 0
A19: Repeat customer | B19: =COUNTIF(Orders!$G$5:$G$504,A19) -> 0 | C19: =COUNTIFS(Orders!$G$5:$G$504,A19,Orders!$W$5:$W$504,"Won") -> 0 | D19: =SUMIFS(Orders!$S$5:$S$504,Orders!$G$5:$G$504,A19,Orders!$W$5:$W$504,"Won") -> 0
A20: Google | B20: =COUNTIF(Orders!$G$5:$G$504,A20) -> 0 | C20: =COUNTIFS(Orders!$G$5:$G$504,A20,Orders!$W$5:$W$504,"Won") -> 0 | D20: =SUMIFS(Orders!$S$5:$S$504,Orders!$G$5:$G$504,A20,Orders!$W$5:$W$504,"Won") -> 0
A21: Other | B21: =COUNTIF(Orders!$G$5:$G$504,A21) -> 0 | C21: =COUNTIFS(Orders!$G$5:$G$504,A21,Orders!$W$5:$W$504,"Won") -> 0 | D21: =SUMIFS(Orders!$S$5:$S$504,Orders!$G$5:$G$504,A21,Orders!$W$5:$W$504,"Won") -> 0
A23: By type | B23: Product lines | C23: Won lines | D23: Revenue won (₹)
A24: Corporate | B24: =COUNTIF(Orders!$E$5:$E$504,A24) -> 5 | C24: =COUNTIFS(Orders!$E$5:$E$504,A24,Orders!$W$5:$W$504,"Won") -> 1 | D24: =SUMIFS(Orders!$S$5:$S$504,Orders!$E$5:$E$504,A24,Orders!$W$5:$W$504,"Won") -> 19800
A25: Personal | B25: =COUNTIF(Orders!$E$5:$E$504,A25) -> 2 | C25: =COUNTIFS(Orders!$E$5:$E$504,A25,Orders!$W$5:$W$504,"Won") -> 1 | D25: =SUMIFS(Orders!$S$5:$S$504,Orders!$E$5:$E$504,A25,Orders!$W$5:$W$504,"Won") -> 32600
A27: By occasion | B27: Product lines | C27: Won lines | D27: Revenue won (₹)
A28: Diwali | B28: =COUNTIF(Orders!$F$5:$F$504,A28) -> 6 | C28: =COUNTIFS(Orders!$F$5:$F$504,A28,Orders!$W$5:$W$504,"Won") -> 2 | D28: =SUMIFS(Orders!$S$5:$S$504,Orders!$F$5:$F$504,A28,Orders!$W$5:$W$504,"Won") -> 52400
A29: Wedding | B29: =COUNTIF(Orders!$F$5:$F$504,A29) -> 0 | C29: =COUNTIFS(Orders!$F$5:$F$504,A29,Orders!$W$5:$W$504,"Won") -> 0 | D29: =SUMIFS(Orders!$S$5:$S$504,Orders!$F$5:$F$504,A29,Orders!$W$5:$W$504,"Won") -> 0
A30: Housewarming | B30: =COUNTIF(Orders!$F$5:$F$504,A30) -> 0 | C30: =COUNTIFS(Orders!$F$5:$F$504,A30,Orders!$W$5:$W$504,"Won") -> 0 | D30: =SUMIFS(Orders!$S$5:$S$504,Orders!$F$5:$F$504,A30,Orders!$W$5:$W$504,"Won") -> 0
A31: Naming ceremony | B31: =COUNTIF(Orders!$F$5:$F$504,A31) -> 0 | C31: =COUNTIFS(Orders!$F$5:$F$504,A31,Orders!$W$5:$W$504,"Won") -> 0 | D31: =SUMIFS(Orders!$S$5:$S$504,Orders!$F$5:$F$504,A31,Orders!$W$5:$W$504,"Won") -> 0
A32: Birthday | B32: =COUNTIF(Orders!$F$5:$F$504,A32) -> 0 | C32: =COUNTIFS(Orders!$F$5:$F$504,A32,Orders!$W$5:$W$504,"Won") -> 0 | D32: =SUMIFS(Orders!$S$5:$S$504,Orders!$F$5:$F$504,A32,Orders!$W$5:$W$504,"Won") -> 0
A33: Pooja / Vratham | B33: =COUNTIF(Orders!$F$5:$F$504,A33) -> 0 | C33: =COUNTIFS(Orders!$F$5:$F$504,A33,Orders!$W$5:$W$504,"Won") -> 0 | D33: =SUMIFS(Orders!$S$5:$S$504,Orders!$F$5:$F$504,A33,Orders!$W$5:$W$504,"Won") -> 0
A34: Sankranti | B34: =COUNTIF(Orders!$F$5:$F$504,A34) -> 0 | C34: =COUNTIFS(Orders!$F$5:$F$504,A34,Orders!$W$5:$W$504,"Won") -> 0 | D34: =SUMIFS(Orders!$S$5:$S$504,Orders!$F$5:$F$504,A34,Orders!$W$5:$W$504,"Won") -> 0
A35: New Year | B35: =COUNTIF(Orders!$F$5:$F$504,A35) -> 0 | C35: =COUNTIFS(Orders!$F$5:$F$504,A35,Orders!$W$5:$W$504,"Won") -> 0 | D35: =SUMIFS(Orders!$S$5:$S$504,Orders!$F$5:$F$504,A35,Orders!$W$5:$W$504,"Won") -> 0
A36: Baby shower | B36: =COUNTIF(Orders!$F$5:$F$504,A36) -> 0 | C36: =COUNTIFS(Orders!$F$5:$F$504,A36,Orders!$W$5:$W$504,"Won") -> 0 | D36: =SUMIFS(Orders!$S$5:$S$504,Orders!$F$5:$F$504,A36,Orders!$W$5:$W$504,"Won") -> 0
A37: Other | B37: =COUNTIF(Orders!$F$5:$F$504,A37) -> 1 | C37: =COUNTIFS(Orders!$F$5:$F$504,A37,Orders!$W$5:$W$504,"Won") -> 0 | D37: =SUMIFS(Orders!$S$5:$S$504,Orders!$F$5:$F$504,A37,Orders!$W$5:$W$504,"Won") -> 0
A39: Status | B39: Product lines
A40: New enquiry | B40: =COUNTIF(Orders!$U$5:$U$504,A40) -> 1
A41: Quoted | B41: =COUNTIF(Orders!$U$5:$U$504,A41) -> 0
A42: Negotiating | B42: =COUNTIF(Orders!$U$5:$U$504,A42) -> 0
A43: Advance received | B43: =COUNTIF(Orders!$U$5:$U$504,A43) -> 0
A44: In production | B44: =COUNTIF(Orders!$U$5:$U$504,A44) -> 0
A45: Dispatched | B45: =COUNTIF(Orders!$U$5:$U$504,A45) -> 0
...

Sheet Discount Slabs
A1: Volume discount slabs
A2: Proposed in the Festive Season Playbook; edit to match your margins. Maximum total discount (cap) is below.
A4: Minimum pieces | B4: Discount
A5: 1 | B5: 0
A6: 25 | B6: 0.05
A7: 50 | B7: 0.08
A8: 100 | B8: 0.12
A9: 250 | B9: 0.15
A11: Discount cap | B11: 0.15

Sheet Products
A1: Product catalogue
A2: From your price list (21 Oct 2026). Fill Cost per item (yellow) to see margin at list price and at the maximum discount.
A4: ID | B4: Name | C4: Category | D4: Description | E4: List price (₹) | F4: Cost per item (₹) | G4: Margin at list | H4: Margin at max discount | I4: Qty won (from Orders) | J4: Revenue won (₹)
A5: 1 | B5: Copper Glass Set | C5: BRASS | D5: Standard glass size | E5: 900 | F5: 600 | G5: =IF(F5="","",(E5-F5)/E5) -> 0.33333333 | H5: =IF(F5="","",(E5*(1-'Discount Slabs'!$B$11)-F5)/(E5*(1-'Discount Slabs'!$B$11))) -> 0.21568627 | I5: =SUMIFS(Orders!$L$5:$L$504,Orders!$J$5:$J$504,A5,Orders!$W$5:$W$504,"Won") -> 0 | J5: =SUMIFS(Orders!$Q$5:$Q$504,Orders!$J$5:$J$504,A5,Orders!$W$5:$W$504,"Won") -> 0
A6: 2 | B6: Spice Box 1 | C6: BRASS | D6: wt 200 gms; 4 inches | E6: 650 | G6: =IF(F6="","",(E6-F6)/E6) | H6: =IF(F6="","",(E6*(1-'Discount Slabs'!$B$11)-F6)/(E6*(1-'Discount Slabs'!$B$11))) | I6: =SUMIFS(Orders!$L$5:$L$504,Orders!$J$5:$J$504,A6,Orders!$W$5:$W$504,"Won") -> 0 | J6: =SUMIFS(Orders!$Q$5:$Q$504,Orders!$J$5:$J$504,A6,Orders!$W$5:$W$504,"Won") -> 0
A7: 3 | B7: Prasadam Bowl 1 | C7: BRASS | D7: wt 65 gms; width 3.3 inches | E7: 420 | G7: =IF(F7="","",(E7-F7)/E7) | H7: =IF(F7="","",(E7*(1-'Discount Slabs'!$B$11)-F7)/(E7*(1-'Discount Slabs'!$B$11))) | I7: =SUMIFS(Orders!$L$5:$L$504,Orders!$J$5:$J$504,A7,Orders!$W$5:$W$504,"Won") -> 0 | J7: =SUMIFS(Orders!$Q$5:$Q$504,Orders!$J$5:$J$504,A7,Orders!$W$5:$W$504,"Won") -> 0
A8: 4 | B8: Spice Box 2 | C8: BRASS | D8: 550 gms; 6 inches | E8: 1200 | G8: =IF(F8="","",(E8-F8)/E8) | H8: =IF(F8="","",(E8*(1-'Discount Slabs'!$B$11)-F8)/(E8*(1-'Discount Slabs'!$B$11))) | I8: =SUMIFS(Orders!$L$5:$L$504,Orders!$J$5:$J$504,A8,Orders!$W$5:$W$504,"Won") -> 0 | J8: =SUMIFS(Orders!$Q$5:$Q$504,Orders!$J$5:$J$504,A8,Orders!$W$5:$W$504,"Won") -> 0
A9: 5 | B9: Gangalam 1 | C9: BRASS | D9: 50 - 90 gms | E9: 420 | G9: =IF(F9="","",(E9-F9)/E9) | H9: =IF(F9="","",(E9*(1-'Discount Slabs'!$B$11)-F9)/(E9*(1-'Discount Slabs'!$B$11))) | I9: =SUMIFS(Orders!$L$5:$L$504,Orders!$J$5:$J$504,A9,Orders!$W$5:$W$504,"Won") -> 0 | J9: =SUMIFS(Orders!$Q$5:$Q$504,Orders!$J$5:$J$504,A9,Orders!$W$5:$W$504,"Won") -> 0
A10: 6 | B10: Spice Box 3 | C10: BRASS | D10: 200 gms; 4 inches | E10: 665 | G10: =IF(F10="","",(E10-F10)/E10) | H10: =IF(F10="","",(E10*(1-'Discount Slabs'!$B$11)-F10)/(E10*(1-'Discount Slabs'!$B$11))) | I10: =SUMIFS(Orders!$L$5:$L$504,Orders!$J$5:$J$504,A10,Orders!$W$5:$W$504,"Won") -> 0 | J10: =SUMIFS(Orders!$Q$5:$Q$504,Orders!$J$5:$J$504,A10,Orders!$W$5:$W$504,"Won") -> 0
A11: 7 | B11: Coffee Dabra Set | C11: BRASS | D11: 120 gms; | E11: 440 | G11: =IF(F11="","",(E11-F11)/E11) | H11: =IF(F11="","",(E11*(1-'Discount Slabs'!$B$11)-F11)/(E11*(1-'Discount Slabs'!$B$11))) | I11: =SUMIFS(Orders!$L$5:$L$504,Orders!$J$5:$J$504,A11,Orders!$W$5:$W$504,"Won") -> 0 | J11: =SUMIFS(Orders!$Q$5:$Q$504,Orders!$J$5:$J$504,A11,Orders!$W$5:$W$504,"Won") -> 0
A12: 8 | B12: Ghee Pot Engraved | C12: BRASS | D12: size 1 | E12: 850 | G12: =IF(F12="","",(E12-F12)/E12) | H12: =IF(F12="","",(E12*(1-'Discount Slabs'!$B$11)-F12)/(E12*(1-'Discount Slabs'!$B$11))) | I12: =SUMIFS(Orders!$L$5:$L$504,Orders!$J$5:$J$504,A12,Orders!$W$5:$W$504,"Won") -> 0 | J12: =SUMIFS(Orders!$Q$5:$Q$504,Orders!$J$5:$J$504,A12,Orders!$W$5:$W$504,"Won") -> 0
A13: 9 | B13: Shanku Chakra Diyas | C13: BRASS | D13: Comes in 2 sizes | E13: 540 | G13: =IF(F13="","",(E13-F13)/E13) | H13: =IF(F13="","",(E13*(1-'Discount Slabs'!$B$11)-F13)/(E13*(1-'Discount Slabs'!$B$11))) | I13: =SUMIFS(Orders!$L$5:$L$504,Orders!$J$5:$J$504,A13,Orders!$W$5:$W$504,"Won") -> 0 | J13: =SUMIFS(Orders!$Q$5:$Q$504,Orders!$J$5:$J$504,A13,Orders!$W$5:$W$504,"Won") -> 0
A14: 10 | B14: Lotus Stand | C14: BRASS | D14: 4 inches | E14: 340 | G14: =IF(F14="","",(E14-F14)/E14) | H14: =IF(F14="","",(E14*(1-'Discount Slabs'!$B$11)-F14)/(E14*(1-'Discount Slabs'!$B$11))) | I14: =SUMIFS(Orders!$L$5:$L$504,Orders!$J$5:$J$504,A14,Orders!$W$5:$W$504,"Won") -> 0 | J14: =SUMIFS(Orders!$Q$5:$Q$504,Orders!$J$5:$J$504,A14,Orders!$W$5:$W$504,"Won") -> 0
A15: 11 | B15: Lotus Diyas | C15: BRASS | D15: Comes in 2 sizes | E15: 430 | F15: 280 | G15: =IF(F15="","",(E15-F15)/E15) -> 0.34883721 | H15: =IF(F15="","",(E15*(1-'Discount Slabs'!$B$11)-F15)/(E15*(1-'Discount Slabs'!$B$11))) -> 0.23392613 | I15: =SUMIFS(Orders!$L$5:$L$504,Orders!$J$5:$J$504,A15,Orders!$W$5:$W$504,"Won") -> 50 | J15: =SUMIFS(Orders!$Q$5:$Q$504,Orders!$J$5:$J$504,A15,Orders!$W$5:$W$504,"Won") -> 19800
A16: 12 | B16: Peacock Bowl | C16: BRASS | D16: 140 gms; 3 inches | E16: 435 | G16: =IF(F16="","",(E16-F16)/E16) | H16: =IF(F16="","",(E16*(1-'Discount Slabs'!$B$11)-F16)/(E16*(1-'Discount Slabs'!$B$11))) | I16: =SUMIFS(Orders!$L$5:$L$504,Orders!$J$5:$J$504,A16,Orders!$W$5:$W$504,"Won") -> 0 | J16: =SUMIFS(Orders!$Q$5:$Q$504,Orders!$J$5:$J$504,A16,Orders!$W$5:$W$504,"Won") -> 0
A17: 13 | B17: Gangalam 2 | C17: BRASS | D17: 150 gms; 3.5 inches | E17: 520 | G17: =IF(F17="","",(E17-F17)/E17) | H17: =IF(F17="","",(E17*(1-'Discount Slabs'!$B$11)-F17)/(E17*(1-'Discount Slabs'!$B$11))) | I17: =SUMIFS(Orders!$L$5:$L$504,Orders!$J$5:$J$504,A17,Orders!$W$5:$W$504,"Won") -> 0 | J17: =SUMIFS(Orders!$Q$5:$Q$504,Orders!$J$5:$J$504,A17,Orders!$W$5:$W$504,"Won") -> 0
A18: 14 | B18: Ghee Pot Plain | C18: BRASS | D18: size 1 | E18: 850 | G18: =IF(F18="","",(E18-F18)/E18) | H18: =IF(F18="","",(E18*(1-'Discount Slabs'!$B$11)-F18)/(E18*(1-'Discount Slabs'!$B$11))) | I18: =SUMIFS(Orders!$L$5:$L$504,Orders!$J$5:$J$504,A18,Orders!$W$5:$W$504,"Won") -> 0 | J18: =SUMIFS(Orders!$Q$5:$Q$504,Orders!$J$5:$J$504,A18,Orders!$W$5:$W$504,"Won") -> 0
A19: 15 | B19: Parrot Kumkum Holder Small | C19: WOODEN HANDICRAFTS | D19: size in the image | E19: 160 | G19: =IF(F19="","",(E19-F19)/E19) | H19: =IF(F19="","",(E19*(1-'Discount Slabs'!$B$11)-F19)/(E19*(1-'Discount Slabs'!$B$11))) | I19: =SUMIFS(Orders!$L$5:$L$504,Orders!$J$5:$J$504,A19,Orders!$W$5:$W$504,"Won") -> 0 | J19: =SUMIFS(Orders!$Q$5:$Q$504,Orders!$J$5:$J$504,A19,Orders!$W$5:$W$504,"Won") -> 0
A20: 16 | B20: Balaji Kumkum Holder | C20: WOODEN HANDICRAFTS | D20: size in the image | E20: 260 | G20: =IF(F20="","",(E20-F20)/E20) | H20: =IF(F20="","",(E20*(1-'Discount Slabs'!$B$11)-F20)/(E20*(1-'Discount Slabs'!$B$11))) | I20: =SUMIFS(Orders!$L$5:$L$504,Orders!$J$5:$J$504,A20,Orders!$W$5:$W$504,"Won") -> 0 | J20: =SUMIFS(Orders!$Q$5:$Q$504,Orders!$J$5:$J$504,A20,Orders!$W$5:$W$504,"Won") -> 0
A21: 17 | B21: Thambulam Kumkum Set | C21: WOODEN HANDICRAFTS | D21: size in the image | E21: 230 | G21: =IF(F21="","",(E21-F21)/E21) | H21: =IF(F21="","",(E21*(1-'Discount Slabs'!$B$11)-F21)/(E21*(1-'Discount Slabs'!$B$11))) | I21: =SUMIFS(Orders!$L$5:$L$504,Orders!$J$5:$J$504,A21,Orders!$W$5:$W$504,"Won") -> 0 | J21: =SUMIFS(Orders!$Q$5:$Q$504,Orders!$J$5:$J$504,A21,Orders!$W$5:$W$504,"Won") -> 0
A22: 18 | B22: Raja Rani Kumkum Holder | C22: WOODEN HANDICRAFTS | D22: size in the image | E22: 220 | G22: =IF(F22="","",(E22-F22)/E22) | H22: =IF(F22="","",(E22*(1-'Discount Slabs'!$B$11)-F22)/(E22*(1-'Discount Slabs'!$B$11))) | I22: =SUMIFS(Orders!$L$5:$L$504,Orders!$J$5:$J$504,A22,Orders!$W$5:$W$504,"Won") -> 0 | J22: =SUMIFS(Orders!$Q$5:$Q$504,Orders!$J$5:$J$504,A22,Orders!$W$5:$W$504,"Won") -> 0
A23: 19 | B23: Balaji Idols 1 | C23: WOODEN HANDICRAFTS | D23: size in the image | E23: 150 | G23: =IF(F23="","",(E23-F23)/E23) | H23: =IF(F23="","",(E23*(1-'Discount Slabs'!$B$11)-F23)/(E23*(1-'Discount Slabs'!$B$11))) | I23: =SUMIFS(Orders!$L$5:$L$504,Orders!$J$5:$J$504,A23,Orders!$W$5:$W$504,"Won") -> 0 | J23: =SUMIFS(Orders!$Q$5:$Q$504,Orders!$J$5:$J$504,A23,Orders!$W$5:$W$504,"Won") -> 0
A24: 20 | B24: Balaji Idols 2 | C24: WOODEN HANDICRAFTS | D24: size in the image | E24: 460 | G24: =IF(F24="","",(E24-F24)/E24) | H24: =IF(F24="","",(E24*(1-'Discount Slabs'!$B$11)-F24)/(E24*(1-'Discount Slabs'!$B$11))) | I24: =SUMIFS(Orders!$L$5:$L$504,Orders!$J$5:$J$504,A24,Orders!$W$5:$W$504,"Won") -> 0 | J24: =SUMIFS(Orders!$Q$5:$Q$504,Orders!$J$5:$J$504,A24,Orders!$W$5:$W$504,"Won") -> 0
A25: 21 | B25: Parrot Kumkum Holder Big | C25: WOODEN HANDICRAFTS | D25: size in the image | E25: 230 | G25: =IF(F25="","",(E25-F25)/E25) | H25: =IF(F25="","",(E25*(1-'Discount Slabs'!$B$11)-F25)/(E25*(1-'Discount Slabs'!$B$11))) | I25: =SUMIFS(Orders!$L$5:$L$504,Orders!$J$5:$J$504,A25,Orders!$W$5:$W$504,"Won") -> 0 | J25: =SUMIFS(Orders!$Q$5:$Q$504,Orders!$J$5:$J$504,A25,Orders!$W$5:$W$504,"Won") -> 0
A26: 22 | B26: Balaji Idols 3 | C26: WOODEN HANDICRAFTS | D26: size in the image | E26: 170 | G26: =IF(F26="","",(E26-F26)/E26) | H26: =IF(F26="","",(E26*(1-'Discount Slabs'!$B$11)-F26)/(E26*(1-'Discount Slabs'!$B$11))) | I26: =SUMIFS(Orders!$L$5:$L$504,Orders!$J$5:$J$504,A26,Orders!$W$5:$W$504,"Won") -> 0 | J26: =SUMIFS(Orders!$Q$5:$Q$504,Orders!$J$5:$J$504,A26,Orders!$W$5:$W$504,"Won") -> 0
A27: 24 | B27: Balaji Idols 4 | C27: WOODEN HANDICRAFTS | D27: size in the image | E27: 800 | G27: =IF(F27="","",(E27-F27)/E27) | H27: =IF(F27="","",(E27*(1-'Discount Slabs'!$B$11)-F27)/(E27*(1-'Discount Slabs'!$B$11))) | I27: =SUMIFS(Orders!$L$5:$L$504,Orders!$J$5:$J$504,A27,Orders!$W$5:$W$504,"Won") -> 0 | J27: =SUMIFS(Orders!$Q$5:$Q$504,Orders!$J$5:$J$504,A27,Orders!$W$5:$W$504,"Won") -> 0
... A62: 60 | B62: Spiritual Book | C62: WOODEN GIFT ITEMS | D62: Standard | E62: 110 | G62: =IF(F62="","",(E62-F62)/E62) | H62: =IF(F62="","",(E62*(1-'Discount Slabs'!$B$11)-F62)/(E62*(1-'Discount Slabs'!$B$11))) | I62: =SUMIFS(Orders!$L$5:$L$504,Orders!$J$5:$J$504,A62,Orders!$W$5:$W$504,"Won") -> 0 | J62: =SUMIFS(Orders!$Q$5:$Q$504,Orders!$J$5:$J$504,A62,Orders!$W$5:$W$504,"Won") -> 0
A63: 61 | B63: Annapakshi Diyas | C63: BRASS | E63: 800 | G63: =IF(F63="","",(E63-F63)/E63) | H63: =IF(F63="","",(E63*(1-'Discount Slabs'!$B$11)-F63)/(E63*(1-'Discount Slabs'!$B$11))) | I63: =SUMIFS(Orders!$L$5:$L$504,Orders!$J$5:$J$504,A63,Orders!$W$5:$W$504,"Won") -> 0 | J63: =SUMIFS(Orders!$Q$5:$Q$504,Orders!$J$5:$J$504,A63,Orders!$W$5:$W$504,"Won") -> 0
A64: 62 | B64: Kolam Tray | C64: METAL GIFTS | D64: 8 inches | E64: 270 | G64: =IF(F64="","",(E64-F64)/E64) | H64: =IF(F64="","",(E64*(1-'Discount Slabs'!$B$11)-F64)/(E64*(1-'Discount Slabs'!$B$11))) | I64: =SUMIFS(Orders!$L$5:$L$504,Orders!$J$5:$J$504,A64,Orders!$W$5:$W$504,"Won") -> 0 | J64: =SUMIFS(Orders!$Q$5:$Q$504,Orders!$J$5:$J$504,A64,Orders!$W$5:$W$504,"Won") -> 0
A65: 64 | B65: Shanku Chakra Bowl | C65: BRASS | D65: 65 gms | E65: 400 | G65: =IF(F65="","",(E65-F65)/E65) | H65: =IF(F65="","",(E65*(1-'Discount Slabs'!$B$11)-F65)/(E65*(1-'Discount Slabs'!$B$11))) | I65: =SUMIFS(Orders!$L$5:$L$504,Orders!$J$5:$J$504,A65,Orders!$W$5:$W$504,"Won") -> 0 | J65: =SUMIFS(Orders!$Q$5:$Q$504,Orders!$J$5:$J$504,A65,Orders!$W$5:$W$504,"Won") -> 0
A66: 66 | B66: Gangalam 3 | C66: BRASS | D66: 140 gms; 3.5 inches | E66: 675 | G66: =IF(F66="","",(E66-F66)/E66) | H66: =IF(F66="","",(E66*(1-'Discount Slabs'!$B$11)-F66)/(E66*(1-'Discount Slabs'!$B$11))) | I66: =SUMIFS(Orders!$L$5:$L$504,Orders!$J$5:$J$504,A66,Orders!$W$5:$W$504,"Won") -> 0 | J66: =SUMIFS(Orders!$Q$5:$Q$504,Orders!$J$5:$J$504,A66,Orders!$W$5:$W$504,"Won") -> 0
A67: 68 | B67: Pichwai Box | C67: JEWELLERY BOX | D67: 4 x 4 inches | E67: 160 | G67: =IF(F67="","",(E67-F67)/E67) | H67: =IF(F67="","",(E67*(1-'Discount Slabs'!$B$11)-F67)/(E67*(1-'Discount Slabs'!$B$11))) | I67: =SUMIFS(Orders!$L$5:$L$504,Orders!$J$5:$J$504,A67,Orders!$W$5:$W$504,"Won") -> 0 | J67: =SUMIFS(Orders!$Q$5:$Q$504,Orders!$J$5:$J$504,A67,Orders!$W$5:$W$504,"Won") -> 0
A68: 69 | B68: Traditional Woman | C68: WOODEN HANDICRAFTS | D68: 4 inches | E68: 280 | G68: =IF(F68="","",(E68-F68)/E68) | H68: =IF(F68="","",(E68*(1-'Discount Slabs'!$B$11)-F68)/(E68*(1-'Discount Slabs'!$B$11))) | I68: =SUMIFS(Orders!$L$5:$L$504,Orders!$J$5:$J$504,A68,Orders!$W$5:$W$504,"Won") -> 0 | J68: =SUMIFS(Orders!$Q$5:$Q$504,Orders!$J$5:$J$504,A68,Orders!$W$5:$W$504,"Won") -> 0
A69: 70 | B69: Traditional Bride & Groom | C69: WOODEN HANDICRAFTS | D69: 4 inches | E69: 475 | G69: =IF(F69="","",(E69-F69)/E69) | H69: =IF(F69="","",(E69*(1-'Discount Slabs'!$B$11)-F69)/(E69*(1-'Discount Slabs'!$B$11))) | I69: =SUMIFS(Orders!$L$5:$L$504,Orders!$J$5:$J$504,A69,Orders!$W$5:$W$504,"Won") -> 0 | J69: =SUMIFS(Orders!$Q$5:$Q$504,Orders!$J$5:$J$504,A69,Orders!$W$5:$W$504,"Won") -> 0
A70: 71 | B70: Thambulam Woman | C70: WOODEN HANDICRAFTS | D70: 4 inches | E70: 320 | G70: =IF(F70="","",(E70-F70)/E70) | H70: =IF(F70="","",(E70*(1-'Discount Slabs'!$B$11)-F70)/(E70*(1-'Discount Slabs'!$B$11))) | I70: =SUMIFS(Orders!$L$5:$L$504,Orders!$J$5:$J$504,A70,Orders!$W$5:$W$504,"Won") -> 0 | J70: =SUMIFS(Orders!$Q$5:$Q$504,Orders!$J$5:$J$504,A70,Orders!$W$5:$W$504,"Won") -> 0
A71: 72 | B71: Lord Ram & Sita | C71: WOODEN HANDICRAFTS | D71: 4 inches | E71: 600 | G71: =IF(F71="","",(E71-F71)/E71) | H71: =IF(F71="","",(E71*(1-'Discount Slabs'!$B$11)-F71)/(E71*(1-'Discount Slabs'!$B$11))) | I71: =SUMIFS(Orders!$L$5:$L$504,Orders!$J$5:$J$504,A71,Orders!$W$5:$W$504,"Won") -> 0 | J71: =SUMIFS(Orders!$Q$5:$Q$504,Orders!$J$5:$J$504,A71,Orders!$W$5:$W$504,"Won") -> 0
A72: 73 | B72: Prasadam Bowl 2 | C72: BRASS | D72: 50 gms; 3 inches | E72: 220 | G72: =IF(F72="","",(E72-F72)/E72) | H72: =IF(F72="","",(E72*(1-'Discount Slabs'!$B$11)-F72)/(E72*(1-'Discount Slabs'!$B$11))) | I72: =SUMIFS(Orders!$L$5:$L$504,Orders!$J$5:$J$504,A72,Orders!$W$5:$W$504,"Won") -> 0 | J72: =SUMIFS(Orders!$Q$5:$Q$504,Orders!$J$5:$J$504,A72,Orders!$W$5:$W$504,"Won") -> 0
A73: 74 | B73: Balaji Idols 7 | C73: BRASS | D73: 3.5 inches | E73: 160 | G73: =IF(F73="","",(E73-F73)/E73) | H73: =IF(F73="","",(E73*(1-'Discount Slabs'!$B$11)-F73)/(E73*(1-'Discount Slabs'!$B$11))) | I73: =SUMIFS(Orders!$L$5:$L$504,Orders!$J$5:$J$504,A73,Orders!$W$5:$W$504,"Won") -> 0 | J73: =SUMIFS(Orders!$Q$5:$Q$504,Orders!$J$5:$J$504,A73,Orders!$W$5:$W$504,"Won") -> 0
A74: 75 | B74: Matki Jar | C74: METAL GIFTS | D74: 6 inches | E74: 320 | G74: =IF(F74="","",(E74-F74)/E74) | H74: =IF(F74="","",(E74*(1-'Discount Slabs'!$B$11)-F74)/(E74*(1-'Discount Slabs'!$B$11))) | I74: =SUMIFS(Orders!$L$5:$L$504,Orders!$J$5:$J$504,A74,Orders!$W$5:$W$504,"Won") -> 0 | J74: =SUMIFS(Orders!$Q$5:$Q$504,Orders!$J$5:$J$504,A74,Orders!$W$5:$W$504,"Won") -> 0
A75: 76 | B75: Gangalam 4 | C75: BRASS | D75: 130 gms | E75: 450 | G75: =IF(F75="","",(E75-F75)/E75) | H75: =IF(F75="","",(E75*(1-'Discount Slabs'!$B$11)-F75)/(E75*(1-'Discount Slabs'!$B$11))) | I75: =SUMIFS(Orders!$L$5:$L$504,Orders!$J$5:$J$504,A75,Orders!$W$5:$W$504,"Won") -> 0 | J75: =SUMIFS(Orders!$Q$5:$Q$504,Orders!$J$5:$J$504,A75,Orders!$W$5:$W$504,"Won") -> 0
...
